## 关于异常处理try和catch放在循环里面或外面的问题讨论 ##
- **try和catch放在for循环里面**  
代码部分：  
```java
		import java.text.ParseException;
		import java.text.SimpleDateFormat;
		import java.util.ArrayList;
		import java.util.Date;
		import java.util.List;

		public class Demo02 {
			public static void main(String[] args) {
				SimpleDateFormat dateFormat = new SimpleDateFormat("yyyy-MM-dd");
				List<Date>list=new ArrayList<>(10);
				for(int cnt1=0;cnt1<10;cnt1++) {
					try {
						Date date = dateFormat.parse("09-12");
						list.add(date);
					}catch (ParseException e) {
						e.printStackTrace();
						System.out.println("ERROR");
					}
				}
			}
		}
```
输出结果为十个"ERROR"说明它执行了十次。  
- **try和catch放在for循环外面**  
代码部分：  
```java  
		import java.text.ParseException;
		import java.text.SimpleDateFormat;
		import java.util.ArrayList;
		import java.util.Date;
		import java.util.List;

		public class Demo02 {
			public static void main(String[] args) {
				SimpleDateFormat dateFormat = new SimpleDateFormat("yyyy-MM-dd");
				List<Date>list=new ArrayList<>(10);
				try {
					for(int cnt1=0;cnt1<10;cnt1++) {
						Date date = dateFormat.parse("09-12");
						list.add(date);
					}
				}catch (ParseException e) {
					e.printStackTrace();
					System.out.println("ERROR");
				}
			}
		}
```		
输出结果只输出了一个"ERROR",说明只执行了一次。  
- **说明**  
try是循环里面的语句时，出现异常后就执行catch里面的语句，之后执行后面的语句，结果后面又是循环，所以又进行下一轮循环。而try在循环外或者说try里面包含循环语句时，若出现异常，也是执行catch语句，完成后就完成了这个try语句，执行之后的语句，那么它就只有一个输出。
